Workbook

Sheet Progress Tracker
A1: Ref | B1: Level | C1: Section | D1: Page Name | F1: URL | G1: Priority | H1: Content | I1: Design | J1: Development | K1: Review | L1: % Complete | M1: Owner | N1: Target Live Date | O1: Notes
A2: 1.0 | B2: 0 | C2: Home | D2: Home | F2: / | G2: P1 | H2: Not started | I2: Not started | J2: Not started | K2: Not started | L2: =COUNTIF(H2:K2,"Complete")/4 -> 0 | O2: Hero direction still open: real warehouse vs product-first UI.
A3: 2.0 | B3: 1 | C3: Solutions | D3: Solutions Hub | F3: /solutions | G3: P1 | H3: Not started | I3: Not started | J3: Not started | K3: Not started | L3: =COUNTIF(H3:K3,"Complete")/4 -> 0
A4: 2.1 | B4: 2 | C4: Solutions | D4: Rack Safety and Intelligence | F4: /solutions/rack-intelligence | G4: P2 | H4: Not started | I4: Not started | J4: Not started | K4: Not started | L4: =COUNTIF(H4:K4,"Complete")/4 -> 0 | O4: Powered by IRDS.
A5: 2.2 | B5: 2 | C5: Solutions | D5: MHE Safety and Productivity | F5: /solutions/mhe-intelligence | G5: P2 | H5: Not started | I5: Not started | J5: Not started | K5: Not started | L5: =COUNTIF(H5:K5,"Complete")/4 -> 0 | O5: Powered by MEPS and RTSS.
A6: 2.3 | B6: 2 | C6: Solutions | D6: Inventory Intelligence | F6: /solutions/inventory-intelligence | G6: P2 | H6: Not started | I6: Not started | J6: Not started | K6: Not started | L6: =COUNTIF(H6:K6,"Complete")/4 -> 0
A7: 2.4 | B7: 2 | C7: Solutions | D7: Warehouse Execution | F7: /solutions/warehouse-execution | G7: P2 | H7: Not started | I7: Not started | J7: Not started | K7: Not started | L7: =COUNTIF(H7:K7,"Complete")/4 -> 0 | O7: Powered by ATOS.
A8: 2.5 | B8: 2 | C8: Solutions | D8: MHE Diagnostics and Maintenance | F8: /solutions/mhe-diagnostics | G8: P2 | H8: Not started | I8: Not started | J8: Not started | K8: Not started | L8: =COUNTIF(H8:K8,"Complete")/4 -> 0 | O8: Powered by IMDS.
A9: 2.6 | B9: 2 | C9: Solutions | D9: Management Intelligence | F9: /solutions/management-intelligence | G9: P2 | H9: Not started | I9: Not started | J9: Not started | K9: Not started | L9: =COUNTIF(H9:K9,"Complete")/4 -> 0 | O9: Powered by AIMS.
A10: 3.0 | B10: 1 | C10: Platform | D10: Platform Hub | F10: /platform | G10: P2 | H10: Not started | I10: Not started | J10: Not started | K10: Not started | L10: =COUNTIF(H10:K10,"Complete")/4 -> 0
D11: DIGITAL TWIN
A12: 3.1 | B12: 2 | C12: Platform | D12: MEPS | F12: /platform/overview | G12: P3 | H12: Not started | I12: Not started | J12: Not started | K12: Not started | L12: =COUNTIF(H12:K12,"Complete")/4 -> 0
A13: 3.3 | B13: 2 | C13: Platform | D13: IRDS | F13: /platform/digital-twin | G13: P3 | H13: Not started | I13: Not started | J13: Not started | K13: Not started | L13: =COUNTIF(H13:K13,"Complete")/4 -> 0
A14: 3.4 | B14: 2 | C14: Platform | D14: ATOS | F14: /platform/ai-operational-intelligence | G14: P3 | H14: Not started | I14: Not started | J14: Not started | K14: Not started | L14: =COUNTIF(H14:K14,"Complete")/4 -> 0
A15: 3.5 | B15: 2 | C15: Platform | D15: RTSS | F15: /platform/execution-engine | G15: P3 | H15: Not started | I15: Not started | J15: Not started | K15: Not started | L15: =COUNTIF(H15:K15,"Complete")/4 -> 0 | O15: ATOS.
A16: 3.6 | B16: 2 | C16: Platform | D16: IMDS | F16: /platform/integrations | G16: P3 | H16: Not started | I16: Not started | J16: Not started | K16: Not started | L16: =COUNTIF(H16:K16,"Complete")/4 -> 0 | O16: WMS, ERP, CCTV, RFID, MHE, maintenance, APIs.
A17: 3.7 | B17: 2 | C17: Platform | D17: AIMS | F17: /platform/security | G17: P3 | H17: Not started | I17: Not started | J17: Not started | K17: Not started | L17: =COUNTIF(H17:K17,"Complete")/4 -> 0 | O17: Footer Security link points here.
A18: 4.0 | B18: 1 | C18: Hardware | D18: Hardware Hub | F18: /hardware | G18: P1 | H18: Not started | I18: Not started | J18: Not started | K18: Not started | L18: =COUNTIF(H18:K18,"Complete")/4 -> 0
A19: 4.1 | B19: 2 | C19: Hardware | D19: AI Vision Camera System | F19: /hardware/ai-vision | G19: P1 | H19: Not started | I19: Not started | J19: Not started | K19: Not started | L19: =COUNTIF(H19:K19,"Complete")/4 -> 0 | O19: Standalone or platform connected.
E20: AI Vision Pro
E21: AI Vision Ultra
E22: AI Vision Max
A23: 4.2 | B23: 2 | C23: Hardware | D23: OmniBox Edge Processors | F23: /hardware/omnibox | G23: P2 | H23: Not started | I23: Not started | J23: Not started | K23: Not started | L23: =COUNTIF(H23:K23,"Complete")/4 -> 0 | O23: Four roles: Edge, AI, Motion, Core.
E24: OmniBox Edge
E25: OmniBox AI
E26: OmniBox Motion
E27: OmniBox Core
A28: 4.3 | B28: 2 | C28: Hardware | D28: RTLS and Location Intelligence | F28: /hardware/rtls | G28: P2 | H28: Not started | I28: Not started | J28: Not started | K28: Not started | L28: =COUNTIF(H28:K28,"Complete")/4 -> 0 | O28: LiDAR-first. Needs a Pilot Stage badge.
E29: LiDAR
E30: Wifi
E31: Bluetooth
E32: UWB
A33: 4.4 | B33: 2 | C33: Hardware | D33: Sensor Stack | F33: /hardware/sensor-stack | G33: P3 | H33: Not started | I33: Not started | J33: Not started | K33: Not started | L33: =COUNTIF(H33:K33,"Complete")/4 -> 0 | O33: Covers all four sensors. Not separate pages.
E34: Access Control
E35: Crash Monitoring System
E36: Speed Monitoring System
E37: Location Monitoring System
E38: Pallet Detection Sensor
E39: Battery Management System
A40: 4.6 | B40: 2 | C40: Hardware | D40: Guided Inspection Systems | E40: Coming Soon | F40: URL TBC | G40: P3 | H40: Not started | I40: Not started | J40: Not started | K40: Not started | L40: =COUNTIF(H40:K40,"Complete")/4 -> 0 | O40: BLOCKED. AirScan and FloorScan have no nav placement or URL yet.
...

Sheet How to use
A1: How to use this tracker
A4: What you update
A5: Content, Design, Development, Review | B5: Four dropdowns per page: Not started, In progress, Blocked, Complete. These are the only cells you normally change.
A6: Owner | B6: Who is accountable for that page.
A7: Target Live Date | B7: Planned publication date.
A8: Priority | B8: P1 launch, P2 phase two, P3 later. Dropdown.
A10: What calculates itself
A11: % Complete | B11: Counts how many of the four stages say Complete, divided by four. One stage done shows 25 percent, all four shows 100 percent. Do not type over it.
A12: Dashboard tab | B12: Every number reads from the tracker. Change a dropdown and the dashboard moves.
A14: Colours
A15: Green | B15: Complete.
A16: Amber | B16: In progress.
A17: Red | B17: Blocked.
A18: Orange row | B18: A page with an unresolved structural decision.
A19: Grey bold row | B19: A top-level tab or hub page.
A21: Open decision
A22: Guided Inspection Systems | B22: AirScan and FloorScan have no navigation placement and no URL. Resolve before the Hardware section can be finished.

Sheet Dashboard
A1: RAMS 2.0 Website - Build Progress
A2: Every figure is a live formula. Update the Progress Tracker tab and this recalculates.
A4: Overall completion
A5: Total pages | B5: =COUNTA('Progress Tracker'!$D$2:$D$99) -> 79
A6: Pages fully complete | B6: =COUNTIF('Progress Tracker'!$L$2:$L$99,1) -> 0
A7: Pages started but not finished | B7: =COUNTIFS('Progress Tracker'!$L$2:$L$99,">0",'Progress Tracker'!$L$2:$L$99,"<1") -> 0
A8: Pages not started | B8: =COUNTIF('Progress Tracker'!$L$2:$L$99,0) -> 62
A9: Overall site progress | B9: =AVERAGE('Progress Tracker'!$L$2:$L$99) -> 0
A11: Progress by stage
A12: Stage | B12: Complete | C12: In progress | D12: Blocked | E12: Not started
A13: Content | B13: =COUNTIF('Progress Tracker'!$H$2:$H$99,"Complete") -> 0 | C13: =COUNTIF('Progress Tracker'!$H$2:$H$99,"In progress") -> 0 | D13: =COUNTIF('Progress Tracker'!$H$2:$H$99,"Blocked") -> 0 | E13: =COUNTIF('Progress Tracker'!$H$2:$H$99,"Not started") -> 62
A14: Design | B14: =COUNTIF('Progress Tracker'!$I$2:$I$99,"Complete") -> 0 | C14: =COUNTIF('Progress Tracker'!$I$2:$I$99,"In progress") -> 0 | D14: =COUNTIF('Progress Tracker'!$I$2:$I$99,"Blocked") -> 0 | E14: =COUNTIF('Progress Tracker'!$I$2:$I$99,"Not started") -> 62
A15: Development | B15: =COUNTIF('Progress Tracker'!$J$2:$J$99,"Complete") -> 0 | C15: =COUNTIF('Progress Tracker'!$J$2:$J$99,"In progress") -> 0 | D15: =COUNTIF('Progress Tracker'!$J$2:$J$99,"Blocked") -> 0 | E15: =COUNTIF('Progress Tracker'!$J$2:$J$99,"Not started") -> 62
A16: Review | B16: =COUNTIF('Progress Tracker'!$K$2:$K$99,"Complete") -> 0 | C16: =COUNTIF('Progress Tracker'!$K$2:$K$99,"In progress") -> 0 | D16: =COUNTIF('Progress Tracker'!$K$2:$K$99,"Blocked") -> 0 | E16: =COUNTIF('Progress Tracker'!$K$2:$K$99,"Not started") -> 62
A18: Progress by section
A19: Section | B19: Pages | C19: Complete | D19: Progress
A20: Home | B20: =COUNTIF('Progress Tracker'!$C$2:$C$99,A20) -> 1 | C20: =COUNTIFS('Progress Tracker'!$C$2:$C$99,A20,'Progress Tracker'!$L$2:$L$99,1) -> 0 | D20: =IFERROR(AVERAGEIF('Progress Tracker'!$C$2:$C$99,A20,'Progress Tracker'!$L$2:$L$99),0) -> 0
A21: Solutions | B21: =COUNTIF('Progress Tracker'!$C$2:$C$99,A21) -> 7 | C21: =COUNTIFS('Progress Tracker'!$C$2:$C$99,A21,'Progress Tracker'!$L$2:$L$99,1) -> 0 | D21: =IFERROR(AVERAGEIF('Progress Tracker'!$C$2:$C$99,A21,'Progress Tracker'!$L$2:$L$99),0) -> 0
A22: Platform | B22: =COUNTIF('Progress Tracker'!$C$2:$C$99,A22) -> 7 | C22: =COUNTIFS('Progress Tracker'!$C$2:$C$99,A22,'Progress Tracker'!$L$2:$L$99,1) -> 0 | D22: =IFERROR(AVERAGEIF('Progress Tracker'!$C$2:$C$99,A22,'Progress Tracker'!$L$2:$L$99),0) -> 0
A23: Hardware | B23: =COUNTIF('Progress Tracker'!$C$2:$C$99,A23) -> 6 | C23: =COUNTIFS('Progress Tracker'!$C$2:$C$99,A23,'Progress Tracker'!$L$2:$L$99,1) -> 0 | D23: =IFERROR(AVERAGEIF('Progress Tracker'!$C$2:$C$99,A23,'Progress Tracker'!$L$2:$L$99),0) -> 0
A24: Services | B24: =COUNTIF('Progress Tracker'!$C$2:$C$99,A24) -> 7 | C24: =COUNTIFS('Progress Tracker'!$C$2:$C$99,A24,'Progress Tracker'!$L$2:$L$99,1) -> 0 | D24: =IFERROR(AVERAGEIF('Progress Tracker'!$C$2:$C$99,A24,'Progress Tracker'!$L$2:$L$99),0) -> 0
A25: Industries | B25: =COUNTIF('Progress Tracker'!$C$2:$C$99,A25) -> 20 | C25: =COUNTIFS('Progress Tracker'!$C$2:$C$99,A25,'Progress Tracker'!$L$2:$L$99,1) -> 0 | D25: =IFERROR(AVERAGEIF('Progress Tracker'!$C$2:$C$99,A25,'Progress Tracker'!$L$2:$L$99),0) -> 0
A26: Resources | B26: =COUNTIF('Progress Tracker'!$C$2:$C$99,A26) -> 12 | C26: =COUNTIFS('Progress Tracker'!$C$2:$C$99,A26,'Progress Tracker'!$L$2:$L$99,1) -> 0 | D26: =IFERROR(AVERAGEIF('Progress Tracker'!$C$2:$C$99,A26,'Progress Tracker'!$L$2:$L$99),0) -> 0
A27: Company | B27: =COUNTIF('Progress Tracker'!$C$2:$C$99,A27) -> 10 | C27: =COUNTIFS('Progress Tracker'!$C$2:$C$99,A27,'Progress Tracker'!$L$2:$L$99,1) -> 0 | D27: =IFERROR(AVERAGEIF('Progress Tracker'!$C$2:$C$99,A27,'Progress Tracker'!$L$2:$L$99),0) -> 0
A28: Campaign | B28: =COUNTIF('Progress Tracker'!$C$2:$C$99,A28) -> 0 | C28: =COUNTIFS('Progress Tracker'!$C$2:$C$99,A28,'Progress Tracker'!$L$2:$L$99,1) -> 0 | D28: =IFERROR(AVERAGEIF('Progress Tracker'!$C$2:$C$99,A28,'Progress Tracker'!$L$2:$L$99),0) -> 0
A29: Conversion | B29: =COUNTIF('Progress Tracker'!$C$2:$C$99,A29) -> 3 | C29: =COUNTIFS('Progress Tracker'!$C$2:$C$99,A29,'Progress Tracker'!$L$2:$L$99,1) -> 0 | D29: =IFERROR(AVERAGEIF('Progress Tracker'!$C$2:$C$99,A29,'Progress Tracker'!$L$2:$L$99),0) -> 0
A30: Footer | B30: =COUNTIF('Progress Tracker'!$C$2:$C$99,A30) -> 4 | C30: =COUNTIFS('Progress Tracker'!$C$2:$C$99,A30,'Progress Tracker'!$L$2:$L$99,1) -> 0 | D30: =IFERROR(AVERAGEIF('Progress Tracker'!$C$2:$C$99,A30,'Progress Tracker'!$L$2:$L$99),0) -> 0
A32: Progress by priority
A33: Priority | B33: Pages | C33: Complete | D33: Progress
A34: P1 | B34: =COUNTIF('Progress Tracker'!$G$2:$G$99,A34) -> 8 | C34: =COUNTIFS('Progress Tracker'!$G$2:$G$99,A34,'Progress Tracker'!$L$2:$L$99,1) -> 0 | D34: =IFERROR(AVERAGEIF('Progress Tracker'!$G$2:$G$99,A34,'Progress Tracker'!$L$2:$L$99),0) -> 0
A35: P2 | B35: =COUNTIF('Progress Tracker'!$G$2:$G$99,A35) -> 18 | C35: =COUNTIFS('Progress Tracker'!$G$2:$G$99,A35,'Progress Tracker'!$L$2:$L$99,1) -> 0 | D35: =IFERROR(AVERAGEIF('Progress Tracker'!$G$2:$G$99,A35,'Progress Tracker'!$L$2:$L$99),0) -> 0
A36: P3 | B36: =COUNTIF('Progress Tracker'!$G$2:$G$99,A36) -> 36 | C36: =COUNTIFS('Progress Tracker'!$G$2:$G$99,A36,'Progress Tracker'!$L$2:$L$99,1) -> 0 | D36: =IFERROR(AVERAGEIF('Progress Tracker'!$G$2:$G$99,A36,'Progress Tracker'!$L$2:$L$99),0) -> 0
A38: Blockers
A39: Stages currently marked Blocked | B39: =COUNTIF('Progress Tracker'!$H$2:$K$99,"Blocked") -> 0
A40: Known open decision: Guided Inspection has no nav placement or URL.
